<?xml version="1.0"?>


<robot name="origins">
	<material name="blue">
		<color rgba="0 0 1 1"/>
	</material>

	<material name="white">
		<color rgba="1 1 1 1"/>
	</material>

	<link name="base_link">
		<visual>
			<geometry>
				<box size="0.4 0.14 0.1"/>
			</geometry>
			<material name="blue"/>
		</visual>
	</link>

	<joint name="right_joint1" type="continuous">
		<parent link="base_link"/>
		<child link="right_arm1"/>
		<origin rpy="0 0 0" xyz="0.2 0 0"/>
	</joint>

	<link name="right_arm1">
		<visual>
			<geometry>
				<box size="0.075 0.1 0.05"/>
			</geometry>
			<origin rpy="0 0 0" xyz="0.0375 0 0"/>
			<material name="white"/>
		</visual>
	</link>

	<joint name="right_joint2" type="continuous">
		<parent link="right_arm1"/>
		<child link="right_arm2"/>
		<origin rpy="0 0 0" xyz="0.075 0 0"/>
	</joint>

	<link name="right_arm2">
		<visual>
			<geometry>
				<box size="0.045 0.075 0.41"/>
			</geometry>
			<origin rpy="0 0 0" xyz="0.0225 0 -0.205"/>
			<material name="white"/>
		</visual>
	</link>

	<joint name="right_joint3" type="continuous">
		<parent link="right_arm2"/>
		<child link="right_arm3"/>
		<origin rpy="0 0 0" xyz="0 0 -0.41"/>
	</joint>

	<link name="right_arm3">
		<visual>
			<geometry>
				<box size="0.1 0.1 0.04"/>
			</geometry>
			<origin rpy="0 0 0" xyz="0.0225 0 0"/>
			<material name="white"/>
		</visual>
	</link>


</robot>